#VRML_SIM R2023b utf8

EXTERNPROTO "https://raw.githubusercontent.com/cyberbotics/webots/R2023b/projects/objects/backgrounds/protos/TexturedBackground.proto"
EXTERNPROTO "https://raw.githubusercontent.com/cyberbotics/webots/R2023b/projects/objects/backgrounds/protos/TexturedBackgroundLight.proto"
EXTERNPROTO "https://raw.githubusercontent.com/cyberbotics/webots/R2023b/projects/objects/floors/protos/Floor.proto"
EXTERNPROTO "https://raw.githubusercontent.com/cyberbotics/webots/R2023b/projects/appearances/protos/Parquetry.proto"
EXTERNPROTO "https://raw.githubusercontent.com/cyberbotics/webots/R2023b/projects/objects/buildings/protos/HouseWithGarage.proto"
EXTERNPROTO "https://raw.githubusercontent.com/cyberbotics/webots/R2023b/projects/objects/road/protos/StraightRoadSegment.proto"
EXTERNPROTO "https://raw.githubusercontent.com/cyberbotics/webots/R2023b/projects/objects/garden/protos/DogHouse.proto"
EXTERNPROTO "https://raw.githubusercontent.com/cyberbotics/webots/R2023b/projects/objects/road/protos/CurvedRoadSegment.proto"
EXTERNPROTO "../protos/FiducialMarkerSign.proto"

WorldInfo {
}
Viewpoint {
  orientation -0.07623155792724166 0.033322056056604155 0.9965331856772991 2.0460909916005288
  position -1.5424593834206024 -14.095499993827273 2.022346019965736
}
TexturedBackground {
}
TexturedBackgroundLight {
}
Floor {
  size 50 50
  appearance Parquetry {
  }
}
Robot {
  translation -5 -8.3 0
  children [
    DEF Body Pose {
      translation 0 0 0.14
      children [
        Shape {
          appearance PBRAppearance {
            baseColor 0.666667 1 0
            roughness 1
            metalness 0
          }
          geometry Cylinder {
            height 0.25
            radius 0.14
          }
        }
      ]
    }
    HingeJoint {
      jointParameters HingeJointParameters {
        position 0.25512886121990136
        axis 0 1 0
        anchor 0 -0.14 0.075
      }
      device [
        RotationalMotor {
          name "StbdMotor"
        }
      ]
      endPoint Solid {
        translation 0 -0.14 0.075
        rotation 0.9839474590393863 0.12617628816141677 -0.1262019895078612 1.5871820453543886
        children [
          DEF Wheel Shape {
            appearance PBRAppearance {
              baseColor 1 0 0
            }
            geometry Cylinder {
              height 0.025
              radius 0.075
            }
          }
        ]
        name "StbdWheel"
        boundingObject USE Wheel
        physics DEF StbdWheelPhysics Physics {
        }
      }
    }
    HingeJoint {
      jointParameters HingeJointParameters {
        position 0.0977947375018185
        axis 0 1 0
        anchor 0 0.14 0.075
      }
      device [
        RotationalMotor {
          name "PortMotor"
        }
      ]
      endPoint Solid {
        translation 1.17832e-05 0.14 0.075
        rotation 0.997614283411043 0.04880968592618164 -0.048819628163872336 1.5733885640433374
        children [
          USE Wheel
        ]
        name "PortWheel"
        boundingObject USE Wheel
        physics USE StbdWheelPhysics
      }
    }
    BallJoint {
      jointParameters BallJointParameters {
        anchor 0.131 0 0.0075
      }
      jointParameters2 JointParameters {
      }
      jointParameters3 JointParameters {
        axis 0 1 0
      }
      endPoint Solid {
        translation 0.131 0 0.0075
        children [
          DEF FrontCaster Shape {
            appearance PBRAppearance {
              baseColor 0 0 0
              roughness 1
              metalness 0
            }
            geometry Sphere {
              radius 0.0195
            }
          }
        ]
        name "FrontCaster"
        boundingObject USE FrontCaster
        physics Physics {
        }
      }
    }
    BallJoint {
      jointParameters BallJointParameters {
        anchor -0.131 0 0.0075
      }
      jointParameters2 JointParameters {
      }
      jointParameters3 JointParameters {
        axis 0 1 0
      }
      endPoint DEF RearCaster Solid {
        translation -0.131 0 0.0075
        children [
          DEF RearCaster Shape {
            appearance PBRAppearance {
              baseColor 0 0 0
            }
            geometry Sphere {
              radius 0.0195
            }
          }
        ]
        name "RearCaster"
        boundingObject USE RearCaster
        physics Physics {
        }
      }
    }
    Solid {
      translation 0 0 0.275
      children [
        DEF GPSHousing Shape {
          appearance PBRAppearance {
            baseColor 0 0 0
          }
          geometry Cylinder {
            height 0.025
            radius 0.05
          }
        }
      ]
      name "GPSHousing"
      boundingObject USE GPSHousing
      physics Physics {
      }
    }
    GPS {
      translation 0 0 0.275
      name "GPSDevice"
    }
    Solid {
      translation 0.13 0 0.25
      children [
        Shape {
          appearance PBRAppearance {
            baseColor 0.752941 0.752941 0.752941
          }
          geometry Box {
            size 0.025 0.05 0.025
          }
        }
      ]
      name "CameraHousing"
    }
    RangeFinder {
      translation 0.14 0 0.25
      name "D435"
    }
  ]
  boundingObject USE Body
  physics Physics {
  }
  controller "testingController"
}
FiducialMarkerSign {
  translation -9.24 -8.3 0
  rotation 0 0 1 1.571
  name "Fid11"
  markerHeight 0.1
  fiducialMarkerFile "../assets/F11.png"
}
FiducialMarkerSign {
  translation -7 -13.5 0
  name "Fid10"
  markerHeight 0.1
  fiducialMarkerFile "../assets/F10.png"
}
FiducialMarkerSign {
  translation -10.32 -13.25 0
  rotation 0 0 1 1.571
  name "Fid09"
  markerHeight 0.1
  fiducialMarkerFile "../assets/F09.png"
}
FiducialMarkerSign {
  translation -10.34 -11.5 0
  rotation 0 0 1 1.571
  name "Fid08"
  markerHeight 0.1
  fiducialMarkerFile "../assets/F08.png"
}
FiducialMarkerSign {
  translation -8.4 -8.75 0
  name "Fid07"
  fiducialMarkerFile "../assets/F07.png"
}
FiducialMarkerSign {
  translation -6 -8 0
  name "Fid06"
  markerHeight 0.1
  fiducialMarkerFile "../assets/F06.png"
}
FiducialMarkerSign {
  translation -3 -8 0
  name "Fid05"
  markerHeight 0.1
  fiducialMarkerFile "../assets/F05.png"
}
FiducialMarkerSign {
  translation 0 -8 0
  name "Fid04"
  markerHeight 0.1
  fiducialMarkerFile "../assets/F04.png"
}
FiducialMarkerSign {
  translation -8 -1.5 0
  name "Fid03"
  markerHeight 0.1
  fiducialMarkerFile "../assets/F03.png"
}
FiducialMarkerSign {
  translation -6 -1.5 0
  name "Fid02"
  markerHeight 0.1
  fiducialMarkerFile "../assets/F02.png"
}
FiducialMarkerSign {
  translation -3 -1.5 0
  name "Fid01"
  markerHeight 0.1
  fiducialMarkerFile "../assets/F01.png"
}
FiducialMarkerSign {
  translation 0 -1.5 0
  name "Fid00"
  markerHeight 0.1
}
DogHouse {
  translation -8.75 -8.3 0
  name "RobotBase"
}
HouseWithGarage {
  translation -15 -10 0
}
StraightRoadSegment {
  translation 4.5 -25 0.005
  rotation 0 0 1 1.571
  name "Street"
  numberOfLanes 1
  rightBorder FALSE
  leftBorder FALSE
  length 50
}
StraightRoadSegment {
  translation -9 -4.75 0.005
  name "Driveway"
  width 6
  numberOfLanes 1
  rightBorder FALSE
  leftBorder FALSE
}
CurvedRoadSegment {
  translation -9.75 -10 0.005
  rotation 0 0 1 -1.571
  name "SidewalkToDriveway"
  width 1.55
  numberOfLanes 1
  rightBorder FALSE
  leftBorder FALSE
  curvatureRadius 2.4
}
StraightRoadSegment {
  translation -9.8 -12.4 0.005
  name "MainSidewalk"
  width 1.55
  numberOfLanes 1
  rightBorder FALSE
  leftBorder FALSE
  length 11
}
StraightRoadSegment {
  translation -7.35 -10 0.005
  rotation 0 0 1 1.571
  name "DrivewaySidewalk"
  width 1.55
  numberOfLanes 1
  rightBorder FALSE
  leftBorder FALSE
  length 3
}
