#VRML_SIM R2023b utf8

EXTERNPROTO "https://raw.githubusercontent.com/cyberbotics/webots/R2023b/projects/objects/backgrounds/protos/TexturedBackground.proto"
EXTERNPROTO "https://raw.githubusercontent.com/cyberbotics/webots/R2023b/projects/objects/backgrounds/protos/TexturedBackgroundLight.proto"
EXTERNPROTO "https://raw.githubusercontent.com/cyberbotics/webots/R2023b/projects/objects/floors/protos/Floor.proto"
EXTERNPROTO "https://raw.githubusercontent.com/cyberbotics/webots/R2023b/projects/appearances/protos/Parquetry.proto"
EXTERNPROTO "https://raw.githubusercontent.com/cyberbotics/webots/R2023b/projects/objects/buildings/protos/HouseWithGarage.proto"
EXTERNPROTO "https://raw.githubusercontent.com/cyberbotics/webots/R2023b/projects/objects/road/protos/StraightRoadSegment.proto"
EXTERNPROTO "https://raw.githubusercontent.com/cyberbotics/webots/R2023b/projects/objects/garden/protos/DogHouse.proto"
EXTERNPROTO "https://raw.githubusercontent.com/cyberbotics/webots/R2023b/projects/objects/road/protos/CurvedRoadSegment.proto"
EXTERNPROTO "../protos/FiducialMarkerSign.proto"
EXTERNPROTO "https://raw.githubusercontent.com/cyberbotics/webots/R2023b/projects/objects/trees/protos/Cypress.proto"
EXTERNPROTO "https://raw.githubusercontent.com/cyberbotics/webots/R2023b/projects/objects/trees/protos/Oak.proto"
EXTERNPROTO "https://raw.githubusercontent.com/cyberbotics/webots/R2023b/projects/objects/trees/protos/Tree.proto"

WorldInfo {
}
Viewpoint {
  orientation -0.21120058730682417 0.04684531715998447 0.976319531803719 2.622246777057286
  position 34.68991749755016 -24.31488690173297 23.20063047090623
}
TexturedBackground {
}
TexturedBackgroundLight {
}
Floor {
  size 50 50
  appearance Parquetry {
  }
}
Robot {
  translation -2.9650476847424336 -10.760261069121238 -0.0003783943446390714
  rotation -3.567442988912667e-05 9.927772629997011e-06 0.9999999993143872 1.5211395425750873
  children [
    DEF Body Pose {
      translation 0 0 0.14
      children [
        Shape {
          appearance PBRAppearance {
            baseColor 0.666667 1 0
            roughness 1
            metalness 0
          }
          geometry Cylinder {
            height 0.25
            radius 0.14
          }
        }
      ]
    }
    HingeJoint {
      jointParameters HingeJointParameters {
        position 10.199642302441758
        axis 0 1 0
        anchor 0 -0.14 0.075
      }
      device [
        RotationalMotor {
          name "StbdMotor"
        }
      ]
      endPoint Solid {
        translation 0 -0.14 0.075
        rotation 0.2772557964378693 -0.6793162763600108 0.6794546489751707 2.600773131577133
        children [
          DEF Wheel Shape {
            appearance PBRAppearance {
              baseColor 1 0 0
            }
            geometry Cylinder {
              height 0.025
              radius 0.075
            }
          }
        ]
        name "StbdWheel"
        boundingObject USE Wheel
        physics DEF StbdWheelPhysics Physics {
        }
        linearVelocity 0.011686754734392658 0.2353242211134239 -0.0006943304574343641
        angularVelocity -3.1376165674209657 0.15582034055281618 5.459434264318467e-06
      }
    }
    HingeJoint {
      jointParameters HingeJointParameters {
        position 10.243075748266046
        axis 0 1 0
        anchor 0 0.14 0.075
      }
      device [
        RotationalMotor {
          name "PortMotor"
        }
      ]
      endPoint Solid {
        translation -8.854767618730324e-06 0.14 0.07500777411684105
        rotation 0.2931724647201533 -0.6759673581088195 0.6761050485695942 2.571340034257131
        children [
          USE Wheel
        ]
        name "PortWheel"
        boundingObject USE Wheel
        physics USE StbdWheelPhysics
        linearVelocity 0.011686922332286371 0.23532449664619925 -0.0006969147897412486
        angularVelocity -3.137616609451334 0.15582034327952796 5.479020673927795e-06
      }
    }
    BallJoint {
      jointParameters BallJointParameters {
        position 2.7341821132295747
        anchor 0.131 0 0.0075
      }
      jointParameters2 JointParameters {
        position -0.3693246625004505
      }
      jointParameters3 JointParameters {
        position 35.44069324398641
        axis 0 1 0
      }
      endPoint Solid {
        translation 0.1308307562611759 -1.8815796744231505e-05 0.007656996303367508
        rotation -0.47675584979308966 -0.4424669980033003 0.7595569862531819 0.34557571463865916
        children [
          DEF FrontCaster Shape {
            appearance PBRAppearance {
              baseColor 0 0 0
              roughness 1
              metalness 0
            }
            geometry Sphere {
              radius 0.0195
            }
          }
        ]
        name "FrontCaster"
        boundingObject USE FrontCaster
        physics Physics {
        }
        linearVelocity 0.011677995324170628 0.23535527847985216 0.0013283303591068371
        angularVelocity -12.069811861965203 0.598849292632265 -0.043994898964386825
      }
    }
    BallJoint {
      jointParameters BallJointParameters {
        position -3.022119425458143
        anchor -0.131 0 0.0075
      }
      jointParameters2 JointParameters {
        position -0.32844733611934185
      }
      jointParameters3 JointParameters {
        position -35.18018969991052
        axis 0 1 0
      }
      endPoint DEF RearCaster Solid {
        translation -0.13118074742473596 3.5126653754602444e-05 0.0076507381673899914
        rotation -0.2307485054348064 0.43523459753303156 0.8702447772608941 -0.3501683274014775
        children [
          DEF RearCaster Shape {
            appearance PBRAppearance {
              baseColor 0 0 0
            }
            geometry Sphere {
              radius 0.0195
            }
          }
        ]
        name "RearCaster"
        boundingObject USE RearCaster
        physics Physics {
        }
        linearVelocity 0.011715374129552699 0.23525362433758962 0.0014172044067784796
        angularVelocity -12.064610196914176 0.600874641573116 0.07525146192330265
      }
    }
    Solid {
      translation 0 0 0.275
      children [
        DEF GPSHousing Shape {
          appearance PBRAppearance {
            baseColor 0 0 0
          }
          geometry Cylinder {
            height 0.025
            radius 0.05
          }
        }
      ]
      name "GPSHousing"
      boundingObject USE GPSHousing
      physics Physics {
      }
    }
    GPS {
      translation 0 0 0.275
      name "GPSDevice"
    }
    Solid {
      translation 0.13 0 0.25
      children [
        Shape {
          appearance PBRAppearance {
            baseColor 0.752941 0.752941 0.752941
          }
          geometry Box {
            size 0.025 0.05 0.025
          }
        }
      ]
      name "CameraHousing"
    }
    Camera {
      translation 0.14 0 0.25
      name "D435RGB"
      width 1920
      height 1080
    }
    RangeFinder {
      translation 0.14 0 0.25
      name "D435RangeFinder"
      width 1280
      height 720
      minRange 0.025
      maxRange 10
    }
    InertialUnit {
      name "attitude"
      resolution 0.0175
    }
    Gyro {
      resolution 0.0175
    }
  ]
  name "StephensTestBot"
  boundingObject USE Body
  physics Physics {
  }
  controller "testingController"
  controllerArgs [
    ""
  ]
  linearVelocity 0.011678442593009316 0.23531125842241488 -0.0007244234068363457
  angularVelocity 0.00010385839982741073 -0.00012113317355304953 8.184328506263614e-05
}
FiducialMarkerSign {
  translation -9.24 -8.3 0
  rotation 0 0 1 1.571
  name "Fid11"
  markerHeight 0.1
  fiducialMarkerFile "../assets/F11.png"
}
FiducialMarkerSign {
  translation -7 -13.5 0
  name "Fid10"
  markerHeight 0.1
  fiducialMarkerFile "../assets/F10.png"
}
FiducialMarkerSign {
  translation -10.32 -13.25 0
  rotation 0 0 1 1.571
  name "Fid09"
  markerHeight 0.1
  fiducialMarkerFile "../assets/F09.png"
}
FiducialMarkerSign {
  translation -10.34 -11.5 0
  rotation 0 0 1 1.571
  name "Fid08"
  markerHeight 0.1
  fiducialMarkerFile "../assets/F08.png"
}
FiducialMarkerSign {
  translation -8.4 -8.75 0
  name "Fid07"
  fiducialMarkerFile "../assets/F07.png"
}
FiducialMarkerSign {
  translation -6 -8 0
  name "Fid06"
  markerHeight 0.1
  fiducialMarkerFile "../assets/F06.png"
}
FiducialMarkerSign {
  translation -3 -8 0
  name "Fid05"
  markerHeight 0.1
  fiducialMarkerFile "../assets/F05.png"
}
FiducialMarkerSign {
  translation 0 -8 0
  name "Fid04"
  markerHeight 0.1
  fiducialMarkerFile "../assets/F04.png"
}
FiducialMarkerSign {
  translation -8 -1.5 0
  name "Fid03"
  markerHeight 0.1
  fiducialMarkerFile "../assets/F03.png"
}
FiducialMarkerSign {
  translation -6 -1.5 0
  name "Fid02"
  markerHeight 0.1
  fiducialMarkerFile "../assets/F02.png"
}
FiducialMarkerSign {
  translation -3 -1.5 0
  name "Fid01"
  markerHeight 0.1
  fiducialMarkerFile "../assets/F01.png"
}
FiducialMarkerSign {
  translation 0 -1.5 0
  name "Fid00"
  markerHeight 0.1
}
DogHouse {
  translation -8.75 -8.3 0
  name "RobotBase"
}
HouseWithGarage {
  translation -15 -10 0
}
StraightRoadSegment {
  translation 4.5 -25 0.005
  rotation 0 0 1 1.571
  name "Street"
  numberOfLanes 1
  rightBorder FALSE
  leftBorder FALSE
  length 50
}
StraightRoadSegment {
  translation -9 -4.75 0.005
  name "Driveway"
  width 6
  numberOfLanes 1
  rightBorder FALSE
  leftBorder FALSE
}
CurvedRoadSegment {
  translation -9.75 -10 0.005
  rotation 0 0 1 -1.571
  name "SidewalkToDriveway"
  width 1.55
  numberOfLanes 1
  rightBorder FALSE
  leftBorder FALSE
  curvatureRadius 2.4
}
StraightRoadSegment {
  translation -10 -12.4 0.005
  name "MainSidewalk"
  width 1.55
  numberOfLanes 1
  rightBorder FALSE
  leftBorder FALSE
  length 11
}
StraightRoadSegment {
  translation -7.35 -10 0.005
  rotation 0 0 1 1.571
  name "DrivewaySidewalk"
  width 1.55
  numberOfLanes 1
  rightBorder FALSE
  leftBorder FALSE
  length 3
}
Cypress {
  translation 0 -24 0
  name "cypress"
}
Cypress {
  translation -2 -24 0
  name "cypress(1)"
}
Cypress {
  translation -4 -24 0
  name "cypress(2)"
}
Cypress {
  translation -6 -24 0
  name "cypress(3)"
}
Cypress {
  translation -8 -24 0
  name "cypress(4)"
}
Cypress {
  translation -10 -24 0
  name "cypress(5)"
}
Cypress {
  translation -12 -24 0
  name "cypress(6)"
}
Cypress {
  translation -14 -24 0
  name "cypress(7)"
}
Cypress {
  translation -16 -24 0
  name "cypress(8)"
}
Oak {
  translation -4 3 0
}
Tree {
  translation -2 -18 0
  scale 3 3 12
}
Tree {
  translation -13 4 0
  name "tree(1)"
  scale 3 3 12
}
Tree {
  translation -2 17 0
  name "tree(2)"
  scale 3 3 12
}
